Workbook

Sheet 01
B2: 45658
B4: REGISTRO DE INGRESO Y SALIDA DE TRABAJADORES Y PERSONAS EXTERNAS
B6: HORARIOS | T6: PATENTE
B7: ING. | C7: SAL. | D7: ING. | E7: SAL. | F7: ING. | G7: SAL. | H7: ING. | I7: SAL. | J7: ING. | K7: SAL. | L7: ING. | M7: SAL. | N7: APELLIDO | O7: NOMBRE | P7: RUT | Q7: DV | R7: CARGO | S7: EMPRESA | T7: Particular | U7: EMPRESA | V7: OBSERVACION
N8: AGÜERO | O8: MARTA | P8: 7009791 | Q8: 5 | R8: JUNIOR ASESOR | S8: PRIVADA | T8: HJ CP 67
N9: AGUILA SANCHEZ | O9: JUAN LUIS | P9: 13739164 | Q9: 3 | R9: CONTROL DE LOGISTICA | S9: TRESOL
N10: AGUILAR HERNANDEZ | O10: FRANCISCO | P10: 15734629 | Q10: 6 | R10: ASISTENTE RRHH | S10: TRESOL | T10: CH VD 16
N11: ALCAINO CARDENAS | O11: CLAUDIO ALEJANDRO | P11: 15847284 | Q11: 8 | R11: ASISTENTE DE LOGISTICA | S11: TRESOL
N12: ALMONACID SOTO | O12: JORGE PATRICIO | P12: 15285593 | Q12: 1 | R12: SOLDADOR | S12: TRESOL | T12: KMR714
N13: ALVARADO ALVARADO | O13: BERNARDO MARCELO | P13: 10106820 | Q13: K | R13: CHOFER | S13: ARIDOS | T13: HD FZ 51
N14: ALVARADO MELLA | O14: LUIS ADOLFO | P14: 20900423 | Q14: 2 | R14: AYUDANTE MECANICO | S14: TRESOL
N15: ALVARADO TORRES | O15: JORGE ANDRÉS | P15: 10772508 | Q15: 3 | R15: ENCARGADO DE ADQUISICIONES | S15: TRESOL
N16: AMPUERO MUÑOZ | O16: RAMON | P16: 13967856 | Q16: 7 | R16: GERENTE COMERCIAL-OPERACIONES | S16: TRESOL | T16: KB GD 89
N17: ANTIÑANCO PACHECO | O17: DANIEL FERNANDO | P17: 15301665 | Q17: 8 | R17: CONDUCTOR | S17: TRESOL
N18: ANTRIS ULLOA | O18: JOSE BENEDICTO | P18: 12714471 | Q18: 0 | R18: SOLDADOR | S18: TRESOL | T18: JJ FX 79
N19: ASENCIO CÁRCAMO | O19: CLAUDIA BELÉN | P19: 19367869 | Q19: 6 | R19: ASISTENTE CONTABLE DE FINANZAS | S19: TRESOL | T19: SR YP 72
N20: AVILA CHACON | O20: JULIO ANDRES | P20: 10587634 | Q20: 3 | R20: OPERADOR MAQUINA | S20: ARIDOS | T20: HS GB 34
N21: BARRIA | O21: PEDRO | P21: 20293903 | Q21: 1 | R21: OPERARIO CONDUCTOR | S21: TRESOL
N22: BARRIENTOS TORRES | O22: KENIA ALEJANDRA | P22: 17889059 | Q22: K | R22: ENCARGADA DE CASINO | S22: TRESOL
N23: BOHLE RODRIGUEZ | O23: BARBARA ALEJANDRA | P23: 18802330 | Q23: 4 | R23: ADMINISTRATIVO | S23: ERSAN
N24: BORDEN MUÑOZ | O24: JORGE AMERICO | P24: 13659758 | Q24: 2 | R24: CONDUCTOR | S24: TRESOL
N25: BUSTAMANTE VILLARROEL | O25: JORGE EDUARDO | P25: 9539333 | Q25: 0 | R25: AYUDANTE MECANICO | S25: TRESOL
N26: CÁCERES AROCA | O26: ROCÍO PAULINA | P26: 20773510 | Q26: 8 | R26: ASISTENTE DE LOGISTICA | S26: TRESOL | T26: CW XR 34
N27: CARCAMO CAUCAU | O27: ROBERTO CARLOS | P27: 13407096 | Q27: K | R27: CONDUCTOR | S27: TRESOL
N28: CARCAMO HUAIQUIN | O28: JAVIERA FRANCISCA | P28: 19962921 | Q28: 2 | R28: ADMINISTRATIVO | S28: TRESOL | T28: SL XY 20
N29: CARCAMO HUAIQUIN | O29: NICOLAS IGNACIO | P29: 18801412 | Q29: 7 | R29: ADMINISTRATIVO | S29: TRESOL
N30: CARCAMO OYARZUN | O30: NICOLAS | P30: 9929269 | Q30: 5 | R30: GERENTE GENERAL | S30: TRESOL | T30: KV BG 16
N31: CARDENAS ARTEAGA | O31: EGON JUAN | P31: 13404337 | Q31: 7 | R31: CONDUCTOR | S31: TRESOL
N32: CARDENAS ARTEAGA | O32: HECTOR ELIECER | P32: 12340833 | Q32: 0 | R32: OPERARIO | S32: TRESOL
N33: CARDENAS ROSAS | O33: ARMIN ANDESON | P33: 19269719 | Q33: 0 | R33: OPERARIO | S33: TRESOL
N34: CARRASCO VERGARA | O34: CARLOS ANYELO | P34: 15263602 | Q34: 4 | R34: OPERARIO | S34: TRESOL
N35: CARRASCO VERGARA | O35: CRISTIAN ISAIAS | P35: 13159173 | Q35: K | R35: CONDUCTOR | S35: TRESOL
N36: CARVAJAL SOTO | O36: FERNANDO MARCELO | P36: 20625206 | Q36: 5 | R36: OPERARIO DE SEGREGACIÓN | S36: TRESOL
N37: CASTRO APABLAZA | O37: JAIME PATRICIO | P37: 9871599 | Q37: 1 | R37: JEFE TALLER | S37: TRESOL
N38: CASTRO ROJAS | O38: ENRIQUE HERNAN | P38: 12215854 | Q38: 3 | R38: CONDUCTOR | S38: TRESOL
N39: CEA OYARZO | O39: OSCAR DANIEL | P39: 18287788 | Q39: 3 | R39: MECANICO | S39: TRESOL | T39: JZ WH 82
N40: COBOS RAMIREZ | O40: YSLANDIN DANNEL | P40: 26572030 | Q40: 7 | R40: OPERARIO | S40: ERSAN
N41: CONTRERAS MILLACHEO | O41: EDUARDO IGNACIO | P41: 18735696 | Q41: 2 | R41: CHOFER | S41: ERSAN | T41: KW HB 79
N42: CORONADO BARRIA | O42: HERNAN | P42: 10264143 | Q42: 4 | R42: JEFE DE FLOTA | S42: TRESOL | T42: JX YX 14
N43: CORONADO CARRASCO | O43: YONATAN ESTEBAN | P43: 17964277 | Q43: 8 | R43: OPERARIO | S43: TRESOL
...

Sheet 02
B2: ='01'!B2:M2+1 -> 45659
B4: REGISTRO DE INGRESO Y SALIDA DE TRABAJADORES Y PERSONAS EXTERNAS
B6: HORARIOS | T6: PATENTE
B7: ING. | C7: SAL. | D7: ING. | E7: SAL. | F7: ING. | G7: SAL. | H7: ING. | I7: SAL. | J7: ING. | K7: SAL. | L7: ING. | M7: SAL. | N7: APELLIDO | O7: NOMBRE | P7: RUT | Q7: DV | R7: CARGO | S7: EMPRESA | T7: Particular | U7: EMPRESA | V7: OBSERVACION
N8: ='01'!N8 -> AGÜERO | O8: ='01'!O8 -> MARTA | P8: ='01'!P8 -> 7009791 | Q8: ='01'!Q8 -> 5 | R8: ='01'!R8 -> JUNIOR ASESOR | S8: ='01'!S8 -> PRIVADA
N9: ='01'!N9 -> AGUILA SANCHEZ | O9: ='01'!O9 -> JUAN LUIS | P9: ='01'!P9 -> 13739164 | Q9: ='01'!Q9 -> 3 | R9: ='01'!R9 -> CONTROL DE LOGISTICA | S9: ='01'!S9 -> TRESOL
N10: ='01'!N10 -> AGUILAR HERNANDEZ | O10: ='01'!O10 -> FRANCISCO | P10: ='01'!P10 -> 15734629 | Q10: ='01'!Q10 -> 6 | R10: ='01'!R10 -> ASISTENTE RRHH | S10: ='01'!S10 -> TRESOL
N11: ='01'!N11 -> ALCAINO CARDENAS | O11: ='01'!O11 -> CLAUDIO ALEJANDRO | P11: ='01'!P11 -> 15847284 | Q11: ='01'!Q11 -> 8 | R11: ='01'!R11 -> ASISTENTE DE LOGISTICA | S11: ='01'!S11 -> TRESOL
N12: ='01'!N12 -> ALMONACID SOTO | O12: ='01'!O12 -> JORGE PATRICIO | P12: ='01'!P12 -> 15285593 | Q12: ='01'!Q12 -> 1 | R12: ='01'!R12 -> SOLDADOR | S12: ='01'!S12 -> TRESOL
N13: ='01'!N13 -> ALVARADO ALVARADO | O13: ='01'!O13 -> BERNARDO MARCELO | P13: ='01'!P13 -> 10106820 | Q13: ='01'!Q13 -> K | R13: ='01'!R13 -> CHOFER | S13: ='01'!S13 -> ARIDOS
N14: ='01'!N14 -> ALVARADO MELLA | O14: ='01'!O14 -> LUIS ADOLFO | P14: ='01'!P14 -> 20900423 | Q14: ='01'!Q14 -> 2 | R14: ='01'!R14 -> AYUDANTE MECANICO | S14: ='01'!S14 -> TRESOL
N15: ='01'!N15 -> ALVARADO TORRES | O15: ='01'!O15 -> JORGE ANDRÉS | P15: ='01'!P15 -> 10772508 | Q15: ='01'!Q15 -> 3 | R15: ='01'!R15 -> ENCARGADO DE ADQUISICIONES | S15: ='01'!S15 -> TRESOL
N16: ='01'!N16 -> AMPUERO MUÑOZ | O16: ='01'!O16 -> RAMON | P16: ='01'!P16 -> 13967856 | Q16: ='01'!Q16 -> 7 | R16: ='01'!R16 -> GERENTE COMERCIAL-OPERACIONES | S16: ='01'!S16 -> TRESOL
N17: ='01'!N17 -> ANTIÑANCO PACHECO | O17: ='01'!O17 -> DANIEL FERNANDO | P17: ='01'!P17 -> 15301665 | Q17: ='01'!Q17 -> 8 | R17: ='01'!R17 -> CONDUCTOR | S17: ='01'!S17 -> TRESOL
N18: ='01'!N18 -> ANTRIS ULLOA | O18: ='01'!O18 -> JOSE BENEDICTO | P18: ='01'!P18 -> 12714471 | Q18: ='01'!Q18 -> 0 | R18: ='01'!R18 -> SOLDADOR | S18: ='01'!S18 -> TRESOL
N19: ='01'!N19 -> ASENCIO CÁRCAMO | O19: ='01'!O19 -> CLAUDIA BELÉN | P19: ='01'!P19 -> 19367869 | Q19: ='01'!Q19 -> 6 | R19: ='01'!R19 -> ASISTENTE CONTABLE DE FINANZAS | S19: ='01'!S19 -> TRESOL
... N147: ='01'!N147 -> 0 | O147: ='01'!O147 -> 0 | P147: ='01'!P147 -> 0 | Q147: ='01'!Q147 -> 0 | R147: ='01'!R147 -> 0 | S147: ='01'!S147 -> 0
B150: EXTERNOS
B151: HORARIOS | T151: PATENTE
B152: ING. | C152: SAL. | D152: ING. | E152: SAL. | F152: ING. | G152: SAL. | H152: ING. | I152: SAL. | J152: ING. | K152: SAL. | L152: ING. | M152: SAL. | N152: APELLIDO | O152: NOMBRE | P152: RUT | Q152: DV | R152: CARGO | S152: EMPRESA | T152: Particular | U152: EMPRESA | V152: OBSERVACION
N153: ='01'!N153 | O153: ='01'!N154 | P153: 16809437 | Q153: K | R153: CONTRATISTA | S153: EXTERNO
N154: ESCOBAR | O154: SEBASTIAN | P154: 22972589 | Q154: 0 | R154: CONTRATISTA
N155: GOMEZ | O155: RODRIGO | P155: 18736326 | Q155: 8 | R155: CONTRATISTA
N156: RIVAL | O156: CRISTIAN | R156: MECANICO | S156: EXTERNO
N157: SEMPE | O157: JOSE | P157: 5533503 | Q157: 6 | R157: REPARTIDOR | S157: MARYUN
N158: MARTINES | O158: JOSUE | P158: 27181315 | Q158: 5 | R158: REPARTIDOR
N159: CADAGAN | O159: JOSE | P159: 17547450 | Q159: 1 | R159: VENDEDOR | S159: KAUFMANN
N160: BARENDS | O160: AUGUSTO | P160: 9047753 | Q160: 6 | R160: PARTICULAR | S160: EMPRESA BARENDS
N161: ARCE | O161: MARCO | P161: 20937246 | Q161: 0 | R161: VENDEDOR | S161: TRACK MARC
N162: CARRASCO | O162: CESAR | R162: JEFE DE OPERACIONES | S162: BRIGA SUR
N163: SAEZ | O163: ESTEBAN | P163: 21457843 | Q163: 3 | R163: REPARTIDOR | S163: T.T.P
N164: CARDENAS | O164: ANDRES | R164: ELECTRICO | S164: externo

Sheet 03
B2: ='02'!B2:M2+1 -> 45660
B4: REGISTRO DE INGRESO Y SALIDA DE TRABAJADORES Y PERSONAS EXTERNAS
B6: HORARIOS | T6: PATENTE
B7: ING. | C7: SAL. | D7: ING. | E7: SAL. | F7: ING. | G7: SAL. | H7: ING. | I7: SAL. | J7: ING. | K7: SAL. | L7: ING. | M7: SAL. | N7: APELLIDO | O7: NOMBRE | P7: RUT | Q7: DV | R7: CARGO | S7: EMPRESA | T7: Particular | U7: EMPRESA | V7: OBSERVACION
N8: AGÜERO | O8: MARTA | P8: 7009791 | Q8: 5 | R8: JUNIOR ASESOR | S8: PRIVADA | T8: HJ CP 67
N9: AGUILA SANCHEZ | O9: JUAN LUIS | P9: 13739164 | Q9: 3 | R9: CONTROL DE LOGISTICA | S9: TRESOL
N10: AGUILAR HERNANDEZ | O10: FRANCISCO | P10: 15734629 | Q10: 6 | R10: ASISTENTE RRHH | S10: TRESOL | T10: CH VD 16
N11: ALCAINO CARDENAS | O11: CLAUDIO ALEJANDRO | P11: 15847284 | Q11: 8 | R11: ASISTENTE DE LOGISTICA | S11: TRESOL
N12: ALMONACID SOTO | O12: JORGE PATRICIO | P12: 15285593 | Q12: 1 | R12: SOLDADOR | S12: TRESOL | T12: KMR714
N13: ALVARADO ALVARADO | O13: BERNARDO MARCELO | P13: 10106820 | Q13: K | R13: CHOFER | S13: ARIDOS | T13: HD FZ 51
N14: ALVARADO MELLA | O14: LUIS ADOLFO | P14: 20900423 | Q14: 2 | R14: AYUDANTE MECANICO | S14: TRESOL
N15: ALVARADO TORRES | O15: JORGE ANDRÉS | P15: 10772508 | Q15: 3 | R15: ENCARGADO DE ADQUISICIONES | S15: TRESOL
N16: AMPUERO MUÑOZ | O16: RAMON | P16: 13967856 | Q16: 7 | R16: GERENTE COMERCIAL-OPERACIONES | S16: TRESOL | T16: KB GD 89
N17: ANTIÑANCO PACHECO | O17: DANIEL FERNANDO | P17: 15301665 | Q17: 8 | R17: CONDUCTOR | S17: TRESOL
N18: ANTRIS ULLOA | O18: JOSE BENEDICTO | P18: 12714471 | Q18: 0 | R18: SOLDADOR | S18: TRESOL | T18: JJ FX 79
N19: ASENCIO CÁRCAMO | O19: CLAUDIA BELÉN | P19: 19367869 | Q19: 6 | R19: ASISTENTE CONTABLE DE FINANZAS | S19: TRESOL | T19: SR YP 72
N20: AVILA CHACON | O20: JULIO ANDRES | P20: 10587634 | Q20: 3 | R20: OPERADOR MAQUINA | S20: ARIDOS | T20: HS GB 34
N21: BARRIA | O21: PEDRO | P21: 20293903 | Q21: 1 | R21: OPERARIO CONDUCTOR | S21: TRESOL
N22: BARRIENTOS TORRES | O22: KENIA ALEJANDRA | P22: 17889059 | Q22: K | R22: ENCARGADA DE CASINO | S22: TRESOL
N23: BOHLE RODRIGUEZ | O23: BARBARA ALEJANDRA | P23: 18802330 | Q23: 4 | R23: ADMINISTRATIVO | S23: ERSAN
N24: BORDEN MUÑOZ | O24: JORGE AMERICO | P24: 13659758 | Q24: 2 | R24: CONDUCTOR | S24: TRESOL
N25: BUSTAMANTE VILLARROEL | O25: JORGE EDUARDO | P25: 9539333 | Q25: 0 | R25: AYUDANTE MECANICO | S25: TRESOL
N26: CÁCERES AROCA | O26: ROCÍO PAULINA | P26: 20773510 | Q26: 8 | R26: ASISTENTE DE LOGISTICA | S26: TRESOL | T26: CW XR 34
N27: CARCAMO CAUCAU | O27: ROBERTO CARLOS | P27: 13407096 | Q27: K | R27: CONDUCTOR | S27: TRESOL
N28: CARCAMO HUAIQUIN | O28: JAVIERA FRANCISCA | P28: 19962921 | Q28: 2 | R28: ADMINISTRATIVO | S28: TRESOL | T28: SL XY 20
N29: CARCAMO HUAIQUIN | O29: NICOLAS IGNACIO | P29: 18801412 | Q29: 7 | R29: ADMINISTRATIVO | S29: TRESOL
N30: CARCAMO OYARZUN | O30: NICOLAS | P30: 9929269 | Q30: 5 | R30: GERENTE GENERAL | S30: TRESOL | T30: KV BG 16
N31: CARDENAS ARTEAGA | O31: EGON JUAN | P31: 13404337 | Q31: 7 | R31: CONDUCTOR | S31: TRESOL
N32: CARDENAS ARTEAGA | O32: HECTOR ELIECER | P32: 12340833 | Q32: 0 | R32: OPERARIO | S32: TRESOL
N33: CARDENAS ROSAS | O33: ARMIN ANDESON | P33: 19269719 | Q33: 0 | R33: OPERARIO | S33: TRESOL
N34: CARRASCO VERGARA | O34: CARLOS ANYELO | P34: 15263602 | Q34: 4 | R34: OPERARIO | S34: TRESOL
N35: CARRASCO VERGARA | O35: CRISTIAN ISAIAS | P35: 13159173 | Q35: K | R35: CONDUCTOR | S35: TRESOL
N36: CARVAJAL SOTO | O36: FERNANDO MARCELO | P36: 20625206 | Q36: 5 | R36: OPERARIO DE SEGREGACIÓN | S36: TRESOL
N37: CASTRO APABLAZA | O37: JAIME PATRICIO | P37: 9871599 | Q37: 1 | R37: JEFE TALLER | S37: TRESOL
N38: CASTRO ROJAS | O38: ENRIQUE HERNAN | P38: 12215854 | Q38: 3 | R38: CONDUCTOR | S38: TRESOL
N39: CEA OYARZO | O39: OSCAR DANIEL | P39: 18287788 | Q39: 3 | R39: MECANICO | S39: TRESOL | T39: JZ WH 82
N40: COBOS RAMIREZ | O40: YSLANDIN DANNEL | P40: 26572030 | Q40: 7 | R40: OPERARIO | S40: ERSAN
N41: CONTRERAS MILLACHEO | O41: EDUARDO IGNACIO | P41: 18735696 | Q41: 2 | R41: CHOFER | S41: ERSAN | T41: KW HB 79
N42: CORONADO BARRIA | O42: HERNAN | P42: 10264143 | Q42: 4 | R42: JEFE DE FLOTA | S42: TRESOL | T42: JX YX 14
N43: CORONADO CARRASCO | O43: YONATAN ESTEBAN | P43: 17964277 | Q43: 8 | R43: OPERARIO | S43: TRESOL
...

Sheet 04
B2: ='03'!B2:M2+1 -> 45661
B4: REGISTRO DE INGRESO Y SALIDA DE TRABAJADORES Y PERSONAS EXTERNAS
B6: HORARIOS | T6: PATENTE
B7: ING. | C7: SAL. | D7: ING. | E7: SAL. | F7: ING. | G7: SAL. | H7: ING. | I7: SAL. | J7: ING. | K7: SAL. | L7: ING. | M7: SAL. | N7: APELLIDO | O7: NOMBRE | P7: RUT | Q7: DV | R7: CARGO | S7: EMPRESA | T7: Particular | U7: EMPRESA | V7: OBSERVACION
N8: AGÜERO | O8: MARTA | P8: 7009791 | Q8: 5 | R8: JUNIOR ASESOR | S8: PRIVADA | T8: HJ CP 67
N9: AGUILA SANCHEZ | O9: JUAN LUIS | P9: 13739164 | Q9: 3 | R9: CONTROL DE LOGISTICA | S9: TRESOL
N10: AGUILAR HERNANDEZ | O10: FRANCISCO | P10: 15734629 | Q10: 6 | R10: ASISTENTE RRHH | S10: TRESOL | T10: CH VD 16
N11: ALCAINO CARDENAS | O11: CLAUDIO ALEJANDRO | P11: 15847284 | Q11: 8 | R11: ASISTENTE DE LOGISTICA | S11: TRESOL
N12: ALMONACID SOTO | O12: JORGE PATRICIO | P12: 15285593 | Q12: 1 | R12: SOLDADOR | S12: TRESOL | T12: KMR714
N13: ALVARADO ALVARADO | O13: BERNARDO MARCELO | P13: 10106820 | Q13: K | R13: CHOFER | S13: ARIDOS | T13: HD FZ 51
N14: ALVARADO MELLA | O14: LUIS ADOLFO | P14: 20900423 | Q14: 2 | R14: AYUDANTE MECANICO | S14: TRESOL
N15: ALVARADO TORRES | O15: JORGE ANDRÉS | P15: 10772508 | Q15: 3 | R15: ENCARGADO DE ADQUISICIONES | S15: TRESOL
N16: AMPUERO MUÑOZ | O16: RAMON | P16: 13967856 | Q16: 7 | R16: GERENTE COMERCIAL-OPERACIONES | S16: TRESOL | T16: KB GD 89
N17: ANTIÑANCO PACHECO | O17: DANIEL FERNANDO | P17: 15301665 | Q17: 8 | R17: CONDUCTOR | S17: TRESOL
N18: ANTRIS ULLOA | O18: JOSE BENEDICTO | P18: 12714471 | Q18: 0 | R18: SOLDADOR | S18: TRESOL | T18: JJ FX 79
N19: ASENCIO CÁRCAMO | O19: CLAUDIA BELÉN | P19: 19367869 | Q19: 6 | R19: ASISTENTE CONTABLE DE FINANZAS | S19: TRESOL | T19: SR YP 72
N20: AVILA CHACON | O20: JULIO ANDRES | P20: 10587634 | Q20: 3 | R20: OPERADOR MAQUINA | S20: ARIDOS | T20: HS GB 34
N21: BARRIA | O21: PEDRO | P21: 20293903 | Q21: 1 | R21: OPERARIO CONDUCTOR | S21: TRESOL
N22: BARRIENTOS TORRES | O22: KENIA ALEJANDRA | P22: 17889059 | Q22: K | R22: ENCARGADA DE CASINO | S22: TRESOL
N23: BOHLE RODRIGUEZ | O23: BARBARA ALEJANDRA | P23: 18802330 | Q23: 4 | R23: ADMINISTRATIVO | S23: ERSAN
N24: BORDEN MUÑOZ | O24: JORGE AMERICO | P24: 13659758 | Q24: 2 | R24: CONDUCTOR | S24: TRESOL
N25: BUSTAMANTE VILLARROEL | O25: JORGE EDUARDO | P25: 9539333 | Q25: 0 | R25: AYUDANTE MECANICO | S25: TRESOL
N26: CÁCERES AROCA | O26: ROCÍO PAULINA | P26: 20773510 | Q26: 8 | R26: ASISTENTE DE LOGISTICA | S26: TRESOL | T26: CW XR 34
N27: CARCAMO CAUCAU | O27: ROBERTO CARLOS | P27: 13407096 | Q27: K | R27: CONDUCTOR | S27: TRESOL
N28: CARCAMO HUAIQUIN | O28: JAVIERA FRANCISCA | P28: 19962921 | Q28: 2 | R28: ADMINISTRATIVO | S28: TRESOL | T28: SL XY 20
N29: CARCAMO HUAIQUIN | O29: NICOLAS IGNACIO | P29: 18801412 | Q29: 7 | R29: ADMINISTRATIVO | S29: TRESOL
N30: CARCAMO OYARZUN | O30: NICOLAS | P30: 9929269 | Q30: 5 | R30: GERENTE GENERAL | S30: TRESOL | T30: KV BG 16
N31: CARDENAS ARTEAGA | O31: EGON JUAN | P31: 13404337 | Q31: 7 | R31: CONDUCTOR | S31: TRESOL
N32: CARDENAS ARTEAGA | O32: HECTOR ELIECER | P32: 12340833 | Q32: 0 | R32: OPERARIO | S32: TRESOL
N33: CARDENAS ROSAS | O33: ARMIN ANDESON | P33: 19269719 | Q33: 0 | R33: OPERARIO | S33: TRESOL
N34: CARRASCO VERGARA | O34: CARLOS ANYELO | P34: 15263602 | Q34: 4 | R34: OPERARIO | S34: TRESOL
N35: CARRASCO VERGARA | O35: CRISTIAN ISAIAS | P35: 13159173 | Q35: K | R35: CONDUCTOR | S35: TRESOL
N36: CARVAJAL SOTO | O36: FERNANDO MARCELO | P36: 20625206 | Q36: 5 | R36: OPERARIO DE SEGREGACIÓN | S36: TRESOL
N37: CASTRO APABLAZA | O37: JAIME PATRICIO | P37: 9871599 | Q37: 1 | R37: JEFE TALLER | S37: TRESOL
N38: CASTRO ROJAS | O38: ENRIQUE HERNAN | P38: 12215854 | Q38: 3 | R38: CONDUCTOR | S38: TRESOL
N39: CEA OYARZO | O39: OSCAR DANIEL | P39: 18287788 | Q39: 3 | R39: MECANICO | S39: TRESOL | T39: JZ WH 82
N40: COBOS RAMIREZ | O40: YSLANDIN DANNEL | P40: 26572030 | Q40: 7 | R40: OPERARIO | S40: ERSAN
N41: CONTRERAS MILLACHEO | O41: EDUARDO IGNACIO | P41: 18735696 | Q41: 2 | R41: CHOFER | S41: ERSAN | T41: KW HB 79
N42: CORONADO BARRIA | O42: HERNAN | P42: 10264143 | Q42: 4 | R42: JEFE DE FLOTA | S42: TRESOL | T42: JX YX 14
N43: CORONADO CARRASCO | O43: YONATAN ESTEBAN | P43: 17964277 | Q43: 8 | R43: OPERARIO | S43: TRESOL
...

Sheet 05
B2: ='04'!B2:M2+1 -> 45662
B4: REGISTRO DE INGRESO Y SALIDA DE TRABAJADORES Y PERSONAS EXTERNAS
B6: HORARIOS | T6: PATENTE
B7: ING. | C7: SAL. | D7: ING. | E7: SAL. | F7: ING. | G7: SAL. | H7: ING. | I7: SAL. | J7: ING. | K7: SAL. | L7: ING. | M7: SAL. | N7: APELLIDO | O7: NOMBRE | P7: RUT | Q7: DV | R7: CARGO | S7: EMPRESA | T7: Particular | U7: EMPRESA | V7: OBSERVACION
N8: AGÜERO | O8: MARTA | P8: 7009791 | Q8: 5 | R8: JUNIOR ASESOR | S8: PRIVADA | T8: HJ CP 67
N9: AGUILA SANCHEZ | O9: JUAN LUIS | P9: 13739164 | Q9: 3 | R9: CONTROL DE LOGISTICA | S9: TRESOL
N10: AGUILAR HERNANDEZ | O10: FRANCISCO | P10: 15734629 | Q10: 6 | R10: ASISTENTE RRHH | S10: TRESOL | T10: CH VD 16
N11: ALCAINO CARDENAS | O11: CLAUDIO ALEJANDRO | P11: 15847284 | Q11: 8 | R11: ASISTENTE DE LOGISTICA | S11: TRESOL
N12: ALMONACID SOTO | O12: JORGE PATRICIO | P12: 15285593 | Q12: 1 | R12: SOLDADOR | S12: TRESOL | T12: KMR714
N13: ALVARADO ALVARADO | O13: BERNARDO MARCELO | P13: 10106820 | Q13: K | R13: CHOFER | S13: ARIDOS | T13: HD FZ 51
N14: ALVARADO MELLA | O14: LUIS ADOLFO | P14: 20900423 | Q14: 2 | R14: AYUDANTE MECANICO | S14: TRESOL
N15: ALVARADO TORRES | O15: JORGE ANDRÉS | P15: 10772508 | Q15: 3 | R15: ENCARGADO DE ADQUISICIONES | S15: TRESOL
N16: AMPUERO MUÑOZ | O16: RAMON | P16: 13967856 | Q16: 7 | R16: GERENTE COMERCIAL-OPERACIONES | S16: TRESOL | T16: KB GD 89
N17: ANTIÑANCO PACHECO | O17: DANIEL FERNANDO | P17: 15301665 | Q17: 8 | R17: CONDUCTOR | S17: TRESOL
N18: ANTRIS ULLOA | O18: JOSE BENEDICTO | P18: 12714471 | Q18: 0 | R18: SOLDADOR | S18: TRESOL | T18: JJ FX 79
N19: ASENCIO CÁRCAMO | O19: CLAUDIA BELÉN | P19: 19367869 | Q19: 6 | R19: ASISTENTE CONTABLE DE FINANZAS | S19: TRESOL | T19: SR YP 72
N20: AVILA CHACON | O20: JULIO ANDRES | P20: 10587634 | Q20: 3 | R20: OPERADOR MAQUINA | S20: ARIDOS | T20: HS GB 34
N21: BARRIA | O21: PEDRO | P21: 20293903 | Q21: 1 | R21: OPERARIO CONDUCTOR | S21: TRESOL
N22: BARRIENTOS TORRES | O22: KENIA ALEJANDRA | P22: 17889059 | Q22: K | R22: ENCARGADA DE CASINO | S22: TRESOL
N23: BOHLE RODRIGUEZ | O23: BARBARA ALEJANDRA | P23: 18802330 | Q23: 4 | R23: ADMINISTRATIVO | S23: ERSAN
N24: BORDEN MUÑOZ | O24: JORGE AMERICO | P24: 13659758 | Q24: 2 | R24: CONDUCTOR | S24: TRESOL
N25: BUSTAMANTE VILLARROEL | O25: JORGE EDUARDO | P25: 9539333 | Q25: 0 | R25: AYUDANTE MECANICO | S25: TRESOL
N26: CÁCERES AROCA | O26: ROCÍO PAULINA | P26: 20773510 | Q26: 8 | R26: ASISTENTE DE LOGISTICA | S26: TRESOL | T26: CW XR 34
N27: CARCAMO CAUCAU | O27: ROBERTO CARLOS | P27: 13407096 | Q27: K | R27: CONDUCTOR | S27: TRESOL
N28: CARCAMO HUAIQUIN | O28: JAVIERA FRANCISCA | P28: 19962921 | Q28: 2 | R28: ADMINISTRATIVO | S28: TRESOL | T28: SL XY 20
N29: CARCAMO HUAIQUIN | O29: NICOLAS IGNACIO | P29: 18801412 | Q29: 7 | R29: ADMINISTRATIVO | S29: TRESOL
N30: CARCAMO OYARZUN | O30: NICOLAS | P30: 9929269 | Q30: 5 | R30: GERENTE GENERAL | S30: TRESOL | T30: KV BG 16
N31: CARDENAS ARTEAGA | O31: EGON JUAN | P31: 13404337 | Q31: 7 | R31: CONDUCTOR | S31: TRESOL
N32: CARDENAS ARTEAGA | O32: HECTOR ELIECER | P32: 12340833 | Q32: 0 | R32: OPERARIO | S32: TRESOL
N33: CARDENAS ROSAS | O33: ARMIN ANDESON | P33: 19269719 | Q33: 0 | R33: OPERARIO | S33: TRESOL
N34: CARRASCO VERGARA | O34: CARLOS ANYELO | P34: 15263602 | Q34: 4 | R34: OPERARIO | S34: TRESOL
N35: CARRASCO VERGARA | O35: CRISTIAN ISAIAS | P35: 13159173 | Q35: K | R35: CONDUCTOR | S35: TRESOL
N36: CARVAJAL SOTO | O36: FERNANDO MARCELO | P36: 20625206 | Q36: 5 | R36: OPERARIO DE SEGREGACIÓN | S36: TRESOL
N37: CASTRO APABLAZA | O37: JAIME PATRICIO | P37: 9871599 | Q37: 1 | R37: JEFE TALLER | S37: TRESOL
N38: CASTRO ROJAS | O38: ENRIQUE HERNAN | P38: 12215854 | Q38: 3 | R38: CONDUCTOR | S38: TRESOL
N39: CEA OYARZO | O39: OSCAR DANIEL | P39: 18287788 | Q39: 3 | R39: MECANICO | S39: TRESOL | T39: JZ WH 82
N40: COBOS RAMIREZ | O40: YSLANDIN DANNEL | P40: 26572030 | Q40: 7 | R40: OPERARIO | S40: ERSAN
N41: CONTRERAS MILLACHEO | O41: EDUARDO IGNACIO | P41: 18735696 | Q41: 2 | R41: CHOFER | S41: ERSAN | T41: KW HB 79
N42: CORONADO BARRIA | O42: HERNAN | P42: 10264143 | Q42: 4 | R42: JEFE DE FLOTA | S42: TRESOL | T42: JX YX 14
N43: CORONADO CARRASCO | O43: YONATAN ESTEBAN | P43: 17964277 | Q43: 8 | R43: OPERARIO | S43: TRESOL
...

Sheet 06
B2: ='05'!B2:M2+1 -> 45663
B4: REGISTRO DE INGRESO Y SALIDA DE TRABAJADORES Y PERSONAS EXTERNAS
B6: HORARIOS | T6: PATENTE
B7: ING. | C7: SAL. | D7: ING. | E7: SAL. | F7: ING. | G7: SAL. | H7: ING. | I7: SAL. | J7: ING. | K7: SAL. | L7: ING. | M7: SAL. | N7: APELLIDO | O7: NOMBRE | P7: RUT | Q7: DV | R7: CARGO | S7: EMPRESA | T7: Particular | U7: EMPRESA | V7: OBSERVACION
N8: AGÜERO | O8: MARTA | P8: 7009791 | Q8: 5 | R8: JUNIOR ASESOR | S8: PRIVADA | T8: HJ CP 67
N9: AGUILA SANCHEZ | O9: JUAN LUIS | P9: 13739164 | Q9: 3 | R9: CONTROL DE LOGISTICA | S9: TRESOL
N10: AGUILAR HERNANDEZ | O10: FRANCISCO | P10: 15734629 | Q10: 6 | R10: ASISTENTE RRHH | S10: TRESOL | T10: CH VD 16
N11: ALCAINO CARDENAS | O11: CLAUDIO ALEJANDRO | P11: 15847284 | Q11: 8 | R11: ASISTENTE DE LOGISTICA | S11: TRESOL
N12: ALMONACID SOTO | O12: JORGE PATRICIO | P12: 15285593 | Q12: 1 | R12: SOLDADOR | S12: TRESOL | T12: KMR714
N13: ALVARADO ALVARADO | O13: BERNARDO MARCELO | P13: 10106820 | Q13: K | R13: CHOFER | S13: ARIDOS | T13: HD FZ 51
N14: ALVARADO MELLA | O14: LUIS ADOLFO | P14: 20900423 | Q14: 2 | R14: AYUDANTE MECANICO | S14: TRESOL
N15: ALVARADO TORRES | O15: JORGE ANDRÉS | P15: 10772508 | Q15: 3 | R15: ENCARGADO DE ADQUISICIONES | S15: TRESOL
N16: AMPUERO MUÑOZ | O16: RAMON | P16: 13967856 | Q16: 7 | R16: GERENTE COMERCIAL-OPERACIONES | S16: TRESOL | T16: KB GD 89
N17: ANTIÑANCO PACHECO | O17: DANIEL FERNANDO | P17: 15301665 | Q17: 8 | R17: CONDUCTOR | S17: TRESOL
N18: ANTRIS ULLOA | O18: JOSE BENEDICTO | P18: 12714471 | Q18: 0 | R18: SOLDADOR | S18: TRESOL | T18: JJ FX 79
N19: ASENCIO CÁRCAMO | O19: CLAUDIA BELÉN | P19: 19367869 | Q19: 6 | R19: ASISTENTE CONTABLE DE FINANZAS | S19: TRESOL | T19: SR YP 72
N20: AVILA CHACON | O20: JULIO ANDRES | P20: 10587634 | Q20: 3 | R20: OPERADOR MAQUINA | S20: ARIDOS | T20: HS GB 34
N21: BARRIA | O21: PEDRO | P21: 20293903 | Q21: 1 | R21: OPERARIO CONDUCTOR | S21: TRESOL
N22: BARRIENTOS TORRES | O22: KENIA ALEJANDRA | P22: 17889059 | Q22: K | R22: ENCARGADA DE CASINO | S22: TRESOL
N23: BOHLE RODRIGUEZ | O23: BARBARA ALEJANDRA | P23: 18802330 | Q23: 4 | R23: ADMINISTRATIVO | S23: ERSAN
N24: BORDEN MUÑOZ | O24: JORGE AMERICO | P24: 13659758 | Q24: 2 | R24: CONDUCTOR | S24: TRESOL
N25: BUSTAMANTE VILLARROEL | O25: JORGE EDUARDO | P25: 9539333 | Q25: 0 | R25: AYUDANTE MECANICO | S25: TRESOL
N26: CÁCERES AROCA | O26: ROCÍO PAULINA | P26: 20773510 | Q26: 8 | R26: ASISTENTE DE LOGISTICA | S26: TRESOL | T26: CW XR 34
N27: CARCAMO CAUCAU | O27: ROBERTO CARLOS | P27: 13407096 | Q27: K | R27: CONDUCTOR | S27: TRESOL
N28: CARCAMO HUAIQUIN | O28: JAVIERA FRANCISCA | P28: 19962921 | Q28: 2 | R28: ADMINISTRATIVO | S28: TRESOL | T28: SL XY 20
N29: CARCAMO HUAIQUIN | O29: NICOLAS IGNACIO | P29: 18801412 | Q29: 7 | R29: ADMINISTRATIVO | S29: TRESOL
N30: CARCAMO OYARZUN | O30: NICOLAS | P30: 9929269 | Q30: 5 | R30: GERENTE GENERAL | S30: TRESOL | T30: KV BG 16
N31: CARDENAS ARTEAGA | O31: EGON JUAN | P31: 13404337 | Q31: 7 | R31: CONDUCTOR | S31: TRESOL
N32: CARDENAS ARTEAGA | O32: HECTOR ELIECER | P32: 12340833 | Q32: 0 | R32: OPERARIO | S32: TRESOL
N33: CARDENAS ROSAS | O33: ARMIN ANDESON | P33: 19269719 | Q33: 0 | R33: OPERARIO | S33: TRESOL
N34: CARRASCO VERGARA | O34: CARLOS ANYELO | P34: 15263602 | Q34: 4 | R34: OPERARIO | S34: TRESOL
N35: CARRASCO VERGARA | O35: CRISTIAN ISAIAS | P35: 13159173 | Q35: K | R35: CONDUCTOR | S35: TRESOL
N36: CARVAJAL SOTO | O36: FERNANDO MARCELO | P36: 20625206 | Q36: 5 | R36: OPERARIO DE SEGREGACIÓN | S36: TRESOL
N37: CASTRO APABLAZA | O37: JAIME PATRICIO | P37: 9871599 | Q37: 1 | R37: JEFE TALLER | S37: TRESOL
N38: CASTRO ROJAS | O38: ENRIQUE HERNAN | P38: 12215854 | Q38: 3 | R38: CONDUCTOR | S38: TRESOL
N39: CEA OYARZO | O39: OSCAR DANIEL | P39: 18287788 | Q39: 3 | R39: MECANICO | S39: TRESOL | T39: JZ WH 82
N40: COBOS RAMIREZ | O40: YSLANDIN DANNEL | P40: 26572030 | Q40: 7 | R40: OPERARIO | S40: ERSAN
N41: CONTRERAS MILLACHEO | O41: EDUARDO IGNACIO | P41: 18735696 | Q41: 2 | R41: CHOFER | S41: ERSAN | T41: KW HB 79
N42: CORONADO BARRIA | O42: HERNAN | P42: 10264143 | Q42: 4 | R42: JEFE DE FLOTA | S42: TRESOL | T42: JX YX 14
N43: CORONADO CARRASCO | O43: YONATAN ESTEBAN | P43: 17964277 | Q43: 8 | R43: OPERARIO | S43: TRESOL
...

Sheet 07
B2: ='06'!B2:M2+1 -> 45664
B4: REGISTRO DE INGRESO Y SALIDA DE TRABAJADORES Y PERSONAS EXTERNAS
B6: HORARIOS | T6: PATENTE
B7: ING. | C7: SAL. | D7: ING. | E7: SAL. | F7: ING. | G7: SAL. | H7: ING. | I7: SAL. | J7: ING. | K7: SAL. | L7: ING. | M7: SAL. | N7: APELLIDO | O7: NOMBRE | P7: RUT | Q7: DV | R7: CARGO | S7: EMPRESA | T7: Particular | U7: EMPRESA | V7: OBSERVACION
N8: AGÜERO | O8: MARTA | P8: 7009791 | Q8: 5 | R8: JUNIOR ASESOR | S8: PRIVADA | T8: HJ CP 67
N9: AGUILA SANCHEZ | O9: JUAN LUIS | P9: 13739164 | Q9: 3 | R9: CONTROL DE LOGISTICA | S9: TRESOL
N10: AGUILAR HERNANDEZ | O10: FRANCISCO | P10: 15734629 | Q10: 6 | R10: ASISTENTE RRHH | S10: TRESOL | T10: CH VD 16
N11: ALCAINO CARDENAS | O11: CLAUDIO ALEJANDRO | P11: 15847284 | Q11: 8 | R11: ASISTENTE DE LOGISTICA | S11: TRESOL
N12: ALMONACID SOTO | O12: JORGE PATRICIO | P12: 15285593 | Q12: 1 | R12: SOLDADOR | S12: TRESOL | T12: KMR714
N13: ALVARADO ALVARADO | O13: BERNARDO MARCELO | P13: 10106820 | Q13: K | R13: CHOFER | S13: ARIDOS | T13: HD FZ 51
N14: ALVARADO MELLA | O14: LUIS ADOLFO | P14: 20900423 | Q14: 2 | R14: AYUDANTE MECANICO | S14: TRESOL
N15: ALVARADO TORRES | O15: JORGE ANDRÉS | P15: 10772508 | Q15: 3 | R15: ENCARGADO DE ADQUISICIONES | S15: TRESOL
N16: AMPUERO MUÑOZ | O16: RAMON | P16: 13967856 | Q16: 7 | R16: GERENTE COMERCIAL-OPERACIONES | S16: TRESOL | T16: KB GD 89
N17: ANTIÑANCO PACHECO | O17: DANIEL FERNANDO | P17: 15301665 | Q17: 8 | R17: CONDUCTOR | S17: TRESOL
N18: ANTRIS ULLOA | O18: JOSE BENEDICTO | P18: 12714471 | Q18: 0 | R18: SOLDADOR | S18: TRESOL | T18: JJ FX 79
N19: ASENCIO CÁRCAMO | O19: CLAUDIA BELÉN | P19: 19367869 | Q19: 6 | R19: ASISTENTE CONTABLE DE FINANZAS | S19: TRESOL | T19: SR YP 72
N20: AVILA CHACON | O20: JULIO ANDRES | P20: 10587634 | Q20: 3 | R20: OPERADOR MAQUINA | S20: ARIDOS | T20: HS GB 34
N21: BARRIA | O21: PEDRO | P21: 20293903 | Q21: 1 | R21: OPERARIO CONDUCTOR | S21: TRESOL
N22: BARRIENTOS TORRES | O22: KENIA ALEJANDRA | P22: 17889059 | Q22: K | R22: ENCARGADA DE CASINO | S22: TRESOL
N23: BOHLE RODRIGUEZ | O23: BARBARA ALEJANDRA | P23: 18802330 | Q23: 4 | R23: ADMINISTRATIVO | S23: ERSAN
N24: BORDEN MUÑOZ | O24: JORGE AMERICO | P24: 13659758 | Q24: 2 | R24: CONDUCTOR | S24: TRESOL
N25: BUSTAMANTE VILLARROEL | O25: JORGE EDUARDO | P25: 9539333 | Q25: 0 | R25: AYUDANTE MECANICO | S25: TRESOL
N26: CÁCERES AROCA | O26: ROCÍO PAULINA | P26: 20773510 | Q26: 8 | R26: ASISTENTE DE LOGISTICA | S26: TRESOL | T26: CW XR 34
N27: CARCAMO CAUCAU | O27: ROBERTO CARLOS | P27: 13407096 | Q27: K | R27: CONDUCTOR | S27: TRESOL
N28: CARCAMO HUAIQUIN | O28: JAVIERA FRANCISCA | P28: 19962921 | Q28: 2 | R28: ADMINISTRATIVO | S28: TRESOL | T28: SL XY 20
N29: CARCAMO HUAIQUIN | O29: NICOLAS IGNACIO | P29: 18801412 | Q29: 7 | R29: ADMINISTRATIVO | S29: TRESOL
N30: CARCAMO OYARZUN | O30: NICOLAS | P30: 9929269 | Q30: 5 | R30: GERENTE GENERAL | S30: TRESOL | T30: KV BG 16
N31: CARDENAS ARTEAGA | O31: EGON JUAN | P31: 13404337 | Q31: 7 | R31: CONDUCTOR | S31: TRESOL
N32: CARDENAS ARTEAGA | O32: HECTOR ELIECER | P32: 12340833 | Q32: 0 | R32: OPERARIO | S32: TRESOL
N33: CARDENAS ROSAS | O33: ARMIN ANDESON | P33: 19269719 | Q33: 0 | R33: OPERARIO | S33: TRESOL
N34: CARRASCO VERGARA | O34: CARLOS ANYELO | P34: 15263602 | Q34: 4 | R34: OPERARIO | S34: TRESOL
N35: CARRASCO VERGARA | O35: CRISTIAN ISAIAS | P35: 13159173 | Q35: K | R35: CONDUCTOR | S35: TRESOL
N36: CARVAJAL SOTO | O36: FERNANDO MARCELO | P36: 20625206 | Q36: 5 | R36: OPERARIO DE SEGREGACIÓN | S36: TRESOL
N37: CASTRO APABLAZA | O37: JAIME PATRICIO | P37: 9871599 | Q37: 1 | R37: JEFE TALLER | S37: TRESOL
N38: CASTRO ROJAS | O38: ENRIQUE HERNAN | P38: 12215854 | Q38: 3 | R38: CONDUCTOR | S38: TRESOL
N39: CEA OYARZO | O39: OSCAR DANIEL | P39: 18287788 | Q39: 3 | R39: MECANICO | S39: TRESOL | T39: JZ WH 82
N40: COBOS RAMIREZ | O40: YSLANDIN DANNEL | P40: 26572030 | Q40: 7 | R40: OPERARIO | S40: ERSAN
N41: CONTRERAS MILLACHEO | O41: EDUARDO IGNACIO | P41: 18735696 | Q41: 2 | R41: CHOFER | S41: ERSAN | T41: KW HB 79
N42: CORONADO BARRIA | O42: HERNAN | P42: 10264143 | Q42: 4 | R42: JEFE DE FLOTA | S42: TRESOL | T42: JX YX 14
N43: CORONADO CARRASCO | O43: YONATAN ESTEBAN | P43: 17964277 | Q43: 8 | R43: OPERARIO | S43: TRESOL
...

Sheet 08
B2: ='07'!B2:M2+1 -> 45665
B4: REGISTRO DE INGRESO Y SALIDA DE TRABAJADORES Y PERSONAS EXTERNAS
B6: HORARIOS | T6: PATENTE
B7: ING. | C7: SAL. | D7: ING. | E7: SAL. | F7: ING. | G7: SAL. | H7: ING. | I7: SAL. | J7: ING. | K7: SAL. | L7: ING. | M7: SAL. | N7: APELLIDO | O7: NOMBRE | P7: RUT | Q7: DV | R7: CARGO | S7: EMPRESA | T7: Particular | U7: EMPRESA | V7: OBSERVACION
N8: AGÜERO | O8: MARTA | P8: 7009791 | Q8: 5 | R8: JUNIOR ASESOR | S8: PRIVADA | T8: HJ CP 67
N9: AGUILA SANCHEZ | O9: JUAN LUIS | P9: 13739164 | Q9: 3 | R9: CONTROL DE LOGISTICA | S9: TRESOL
N10: AGUILAR HERNANDEZ | O10: FRANCISCO | P10: 15734629 | Q10: 6 | R10: ASISTENTE RRHH | S10: TRESOL | T10: CH VD 16
N11: ALCAINO CARDENAS | O11: CLAUDIO ALEJANDRO | P11: 15847284 | Q11: 8 | R11: ASISTENTE DE LOGISTICA | S11: TRESOL
N12: ALMONACID SOTO | O12: JORGE PATRICIO | P12: 15285593 | Q12: 1 | R12: SOLDADOR | S12: TRESOL | T12: KMR714
N13: ALVARADO ALVARADO | O13: BERNARDO MARCELO | P13: 10106820 | Q13: K | R13: CHOFER | S13: ARIDOS | T13: HD FZ 51
N14: ALVARADO MELLA | O14: LUIS ADOLFO | P14: 20900423 | Q14: 2 | R14: AYUDANTE MECANICO | S14: TRESOL
N15: ALVARADO TORRES | O15: JORGE ANDRÉS | P15: 10772508 | Q15: 3 | R15: ENCARGADO DE ADQUISICIONES | S15: TRESOL
N16: AMPUERO MUÑOZ | O16: RAMON | P16: 13967856 | Q16: 7 | R16: GERENTE COMERCIAL-OPERACIONES | S16: TRESOL | T16: KB GD 89
N17: ANTIÑANCO PACHECO | O17: DANIEL FERNANDO | P17: 15301665 | Q17: 8 | R17: CONDUCTOR | S17: TRESOL
N18: ANTRIS ULLOA | O18: JOSE BENEDICTO | P18: 12714471 | Q18: 0 | R18: SOLDADOR | S18: TRESOL | T18: JJ FX 79
N19: ASENCIO CÁRCAMO | O19: CLAUDIA BELÉN | P19: 19367869 | Q19: 6 | R19: ASISTENTE CONTABLE DE FINANZAS | S19: TRESOL | T19: SR YP 72
N20: AVILA CHACON | O20: JULIO ANDRES | P20: 10587634 | Q20: 3 | R20: OPERADOR MAQUINA | S20: ARIDOS | T20: HS GB 34
N21: BARRIA | O21: PEDRO | P21: 20293903 | Q21: 1 | R21: OPERARIO CONDUCTOR | S21: TRESOL
N22: BARRIENTOS TORRES | O22: KENIA ALEJANDRA | P22: 17889059 | Q22: K | R22: ENCARGADA DE CASINO | S22: TRESOL
N23: BOHLE RODRIGUEZ | O23: BARBARA ALEJANDRA | P23: 18802330 | Q23: 4 | R23: ADMINISTRATIVO | S23: ERSAN
N24: BORDEN MUÑOZ | O24: JORGE AMERICO | P24: 13659758 | Q24: 2 | R24: CONDUCTOR | S24: TRESOL
N25: BUSTAMANTE VILLARROEL | O25: JORGE EDUARDO | P25: 9539333 | Q25: 0 | R25: AYUDANTE MECANICO | S25: TRESOL
N26: CÁCERES AROCA | O26: ROCÍO PAULINA | P26: 20773510 | Q26: 8 | R26: ASISTENTE DE LOGISTICA | S26: TRESOL | T26: CW XR 34
N27: CARCAMO CAUCAU | O27: ROBERTO CARLOS | P27: 13407096 | Q27: K | R27: CONDUCTOR | S27: TRESOL
N28: CARCAMO HUAIQUIN | O28: JAVIERA FRANCISCA | P28: 19962921 | Q28: 2 | R28: ADMINISTRATIVO | S28: TRESOL | T28: SL XY 20
N29: CARCAMO HUAIQUIN | O29: NICOLAS IGNACIO | P29: 18801412 | Q29: 7 | R29: ADMINISTRATIVO | S29: TRESOL
N30: CARCAMO OYARZUN | O30: NICOLAS | P30: 9929269 | Q30: 5 | R30: GERENTE GENERAL | S30: TRESOL | T30: KV BG 16
N31: CARDENAS ARTEAGA | O31: EGON JUAN | P31: 13404337 | Q31: 7 | R31: CONDUCTOR | S31: TRESOL
N32: CARDENAS ARTEAGA | O32: HECTOR ELIECER | P32: 12340833 | Q32: 0 | R32: OPERARIO | S32: TRESOL
N33: CARDENAS ROSAS | O33: ARMIN ANDESON | P33: 19269719 | Q33: 0 | R33: OPERARIO | S33: TRESOL
N34: CARRASCO VERGARA | O34: CARLOS ANYELO | P34: 15263602 | Q34: 4 | R34: OPERARIO | S34: TRESOL
N35: CARRASCO VERGARA | O35: CRISTIAN ISAIAS | P35: 13159173 | Q35: K | R35: CONDUCTOR | S35: TRESOL
N36: CARVAJAL SOTO | O36: FERNANDO MARCELO | P36: 20625206 | Q36: 5 | R36: OPERARIO DE SEGREGACIÓN | S36: TRESOL
N37: CASTRO APABLAZA | O37: JAIME PATRICIO | P37: 9871599 | Q37: 1 | R37: JEFE TALLER | S37: TRESOL
N38: CASTRO ROJAS | O38: ENRIQUE HERNAN | P38: 12215854 | Q38: 3 | R38: CONDUCTOR | S38: TRESOL
N39: CEA OYARZO | O39: OSCAR DANIEL | P39: 18287788 | Q39: 3 | R39: MECANICO | S39: TRESOL | T39: JZ WH 82
N40: COBOS RAMIREZ | O40: YSLANDIN DANNEL | P40: 26572030 | Q40: 7 | R40: OPERARIO | S40: ERSAN
N41: CONTRERAS MILLACHEO | O41: EDUARDO IGNACIO | P41: 18735696 | Q41: 2 | R41: CHOFER | S41: ERSAN | T41: KW HB 79
N42: CORONADO BARRIA | O42: HERNAN | P42: 10264143 | Q42: 4 | R42: JEFE DE FLOTA | S42: TRESOL | T42: JX YX 14
N43: CORONADO CARRASCO | O43: YONATAN ESTEBAN | P43: 17964277 | Q43: 8 | R43: OPERARIO | S43: TRESOL
...

Sheet 09
B2: ='08'!B2:M2+1 -> 45666
B4: REGISTRO DE INGRESO Y SALIDA DE TRABAJADORES Y PERSONAS EXTERNAS
B6: HORARIOS | T6: PATENTE
B7: ING. | C7: SAL. | D7: ING. | E7: SAL. | F7: ING. | G7: SAL. | H7: ING. | I7: SAL. | J7: ING. | K7: SAL. | L7: ING. | M7: SAL. | N7: APELLIDO | O7: NOMBRE | P7: RUT | Q7: DV | R7: CARGO | S7: EMPRESA | T7: Particular | U7: EMPRESA | V7: OBSERVACION
N8: AGÜERO | O8: MARTA | P8: 7009791 | Q8: 5 | R8: JUNIOR ASESOR | S8: PRIVADA | T8: HJ CP 67
N9: AGUILA SANCHEZ | O9: JUAN LUIS | P9: 13739164 | Q9: 3 | R9: CONTROL DE LOGISTICA | S9: TRESOL
N10: AGUILAR HERNANDEZ | O10: FRANCISCO | P10: 15734629 | Q10: 6 | R10: ASISTENTE RRHH | S10: TRESOL | T10: CH VD 16
N11: ALCAINO CARDENAS | O11: CLAUDIO ALEJANDRO | P11: 15847284 | Q11: 8 | R11: ASISTENTE DE LOGISTICA | S11: TRESOL
N12: ALMONACID SOTO | O12: JORGE PATRICIO | P12: 15285593 | Q12: 1 | R12: SOLDADOR | S12: TRESOL | T12: KMR714
N13: ALVARADO ALVARADO | O13: BERNARDO MARCELO | P13: 10106820 | Q13: K | R13: CHOFER | S13: ARIDOS | T13: HD FZ 51
N14: ALVARADO MELLA | O14: LUIS ADOLFO | P14: 20900423 | Q14: 2 | R14: AYUDANTE MECANICO | S14: TRESOL
N15: ALVARADO TORRES | O15: JORGE ANDRÉS | P15: 10772508 | Q15: 3 | R15: ENCARGADO DE ADQUISICIONES | S15: TRESOL
N16: AMPUERO MUÑOZ | O16: RAMON | P16: 13967856 | Q16: 7 | R16: GERENTE COMERCIAL-OPERACIONES | S16: TRESOL | T16: KB GD 89
N17: ANTIÑANCO PACHECO | O17: DANIEL FERNANDO | P17: 15301665 | Q17: 8 | R17: CONDUCTOR | S17: TRESOL
N18: ANTRIS ULLOA | O18: JOSE BENEDICTO | P18: 12714471 | Q18: 0 | R18: SOLDADOR | S18: TRESOL | T18: JJ FX 79
N19: ASENCIO CÁRCAMO | O19: CLAUDIA BELÉN | P19: 19367869 | Q19: 6 | R19: ASISTENTE CONTABLE DE FINANZAS | S19: TRESOL | T19: SR YP 72
N20: AVILA CHACON | O20: JULIO ANDRES | P20: 10587634 | Q20: 3 | R20: OPERADOR MAQUINA | S20: ARIDOS | T20: HS GB 34
N21: BARRIA | O21: PEDRO | P21: 20293903 | Q21: 1 | R21: OPERARIO CONDUCTOR | S21: TRESOL
N22: BARRIENTOS TORRES | O22: KENIA ALEJANDRA | P22: 17889059 | Q22: K | R22: ENCARGADA DE CASINO | S22: TRESOL
N23: BOHLE RODRIGUEZ | O23: BARBARA ALEJANDRA | P23: 18802330 | Q23: 4 | R23: ADMINISTRATIVO | S23: ERSAN
N24: BORDEN MUÑOZ | O24: JORGE AMERICO | P24: 13659758 | Q24: 2 | R24: CONDUCTOR | S24: TRESOL
N25: BUSTAMANTE VILLARROEL | O25: JORGE EDUARDO | P25: 9539333 | Q25: 0 | R25: AYUDANTE MECANICO | S25: TRESOL
N26: CÁCERES AROCA | O26: ROCÍO PAULINA | P26: 20773510 | Q26: 8 | R26: ASISTENTE DE LOGISTICA | S26: TRESOL | T26: CW XR 34
N27: CARCAMO CAUCAU | O27: ROBERTO CARLOS | P27: 13407096 | Q27: K | R27: CONDUCTOR | S27: TRESOL
N28: CARCAMO HUAIQUIN | O28: JAVIERA FRANCISCA | P28: 19962921 | Q28: 2 | R28: ADMINISTRATIVO | S28: TRESOL | T28: SL XY 20
N29: CARCAMO HUAIQUIN | O29: NICOLAS IGNACIO | P29: 18801412 | Q29: 7 | R29: ADMINISTRATIVO | S29: TRESOL
N30: CARCAMO OYARZUN | O30: NICOLAS | P30: 9929269 | Q30: 5 | R30: GERENTE GENERAL | S30: TRESOL | T30: KV BG 16
N31: CARDENAS ARTEAGA | O31: EGON JUAN | P31: 13404337 | Q31: 7 | R31: CONDUCTOR | S31: TRESOL
N32: CARDENAS ARTEAGA | O32: HECTOR ELIECER | P32: 12340833 | Q32: 0 | R32: OPERARIO | S32: TRESOL
N33: CARDENAS ROSAS | O33: ARMIN ANDESON | P33: 19269719 | Q33: 0 | R33: OPERARIO | S33: TRESOL
N34: CARRASCO VERGARA | O34: CARLOS ANYELO | P34: 15263602 | Q34: 4 | R34: OPERARIO | S34: TRESOL
N35: CARRASCO VERGARA | O35: CRISTIAN ISAIAS | P35: 13159173 | Q35: K | R35: CONDUCTOR | S35: TRESOL
N36: CARVAJAL SOTO | O36: FERNANDO MARCELO | P36: 20625206 | Q36: 5 | R36: OPERARIO DE SEGREGACIÓN | S36: TRESOL
N37: CASTRO APABLAZA | O37: JAIME PATRICIO | P37: 9871599 | Q37: 1 | R37: JEFE TALLER | S37: TRESOL
N38: CASTRO ROJAS | O38: ENRIQUE HERNAN | P38: 12215854 | Q38: 3 | R38: CONDUCTOR | S38: TRESOL
N39: CEA OYARZO | O39: OSCAR DANIEL | P39: 18287788 | Q39: 3 | R39: MECANICO | S39: TRESOL | T39: JZ WH 82
N40: COBOS RAMIREZ | O40: YSLANDIN DANNEL | P40: 26572030 | Q40: 7 | R40: OPERARIO | S40: ERSAN
N41: CONTRERAS MILLACHEO | O41: EDUARDO IGNACIO | P41: 18735696 | Q41: 2 | R41: CHOFER | S41: ERSAN | T41: KW HB 79
N42: CORONADO BARRIA | O42: HERNAN | P42: 10264143 | Q42: 4 | R42: JEFE DE FLOTA | S42: TRESOL | T42: JX YX 14
N43: CORONADO CARRASCO | O43: YONATAN ESTEBAN | P43: 17964277 | Q43: 8 | R43: OPERARIO | S43: TRESOL
...

Sheet 10
B2: ='09'!B2:M2+1 -> 45667
B4: REGISTRO DE INGRESO Y SALIDA DE TRABAJADORES Y PERSONAS EXTERNAS
B6: HORARIOS | T6: PATENTE
B7: ING. | C7: SAL. | D7: ING. | E7: SAL. | F7: ING. | G7: SAL. | H7: ING. | I7: SAL. | J7: ING. | K7: SAL. | L7: ING. | M7: SAL. | N7: APELLIDO | O7: NOMBRE | P7: RUT | Q7: DV | R7: CARGO | S7: EMPRESA | T7: Particular | U7: EMPRESA | V7: OBSERVACION
N8: AGÜERO | O8: MARTA | P8: 7009791 | Q8: 5 | R8: JUNIOR ASESOR | S8: PRIVADA | T8: HJ CP 67
N9: AGUILA SANCHEZ | O9: JUAN LUIS | P9: 13739164 | Q9: 3 | R9: CONTROL DE LOGISTICA | S9: TRESOL
N10: AGUILAR HERNANDEZ | O10: FRANCISCO | P10: 15734629 | Q10: 6 | R10: ASISTENTE RRHH | S10: TRESOL | T10: CH VD 16
N11: ALCAINO CARDENAS | O11: CLAUDIO ALEJANDRO | P11: 15847284 | Q11: 8 | R11: ASISTENTE DE LOGISTICA | S11: TRESOL
N12: ALMONACID SOTO | O12: JORGE PATRICIO | P12: 15285593 | Q12: 1 | R12: SOLDADOR | S12: TRESOL | T12: KMR714
N13: ALVARADO ALVARADO | O13: BERNARDO MARCELO | P13: 10106820 | Q13: K | R13: CHOFER | S13: ARIDOS | T13: HD FZ 51
N14: ALVARADO MELLA | O14: LUIS ADOLFO | P14: 20900423 | Q14: 2 | R14: AYUDANTE MECANICO | S14: TRESOL
N15: ALVARADO TORRES | O15: JORGE ANDRÉS | P15: 10772508 | Q15: 3 | R15: ENCARGADO DE ADQUISICIONES | S15: TRESOL
N16: AMPUERO MUÑOZ | O16: RAMON | P16: 13967856 | Q16: 7 | R16: GERENTE COMERCIAL-OPERACIONES | S16: TRESOL | T16: KB GD 89
N17: ANTIÑANCO PACHECO | O17: DANIEL FERNANDO | P17: 15301665 | Q17: 8 | R17: CONDUCTOR | S17: TRESOL
N18: ANTRIS ULLOA | O18: JOSE BENEDICTO | P18: 12714471 | Q18: 0 | R18: SOLDADOR | S18: TRESOL | T18: JJ FX 79
N19: ASENCIO CÁRCAMO | O19: CLAUDIA BELÉN | P19: 19367869 | Q19: 6 | R19: ASISTENTE CONTABLE DE FINANZAS | S19: TRESOL | T19: SR YP 72
N20: AVILA CHACON | O20: JULIO ANDRES | P20: 10587634 | Q20: 3 | R20: OPERADOR MAQUINA | S20: ARIDOS | T20: HS GB 34
N21: BARRIA | O21: PEDRO | P21: 20293903 | Q21: 1 | R21: OPERARIO CONDUCTOR | S21: TRESOL
N22: BARRIENTOS TORRES | O22: KENIA ALEJANDRA | P22: 17889059 | Q22: K | R22: ENCARGADA DE CASINO | S22: TRESOL
N23: BOHLE RODRIGUEZ | O23: BARBARA ALEJANDRA | P23: 18802330 | Q23: 4 | R23: ADMINISTRATIVO | S23: ERSAN
N24: BORDEN MUÑOZ | O24: JORGE AMERICO | P24: 13659758 | Q24: 2 | R24: CONDUCTOR | S24: TRESOL
N25: BUSTAMANTE VILLARROEL | O25: JORGE EDUARDO | P25: 9539333 | Q25: 0 | R25: AYUDANTE MECANICO | S25: TRESOL
N26: CÁCERES AROCA | O26: ROCÍO PAULINA | P26: 20773510 | Q26: 8 | R26: ASISTENTE DE LOGISTICA | S26: TRESOL | T26: CW XR 34
N27: CARCAMO CAUCAU | O27: ROBERTO CARLOS | P27: 13407096 | Q27: K | R27: CONDUCTOR | S27: TRESOL
N28: CARCAMO HUAIQUIN | O28: JAVIERA FRANCISCA | P28: 19962921 | Q28: 2 | R28: ADMINISTRATIVO | S28: TRESOL | T28: SL XY 20
N29: CARCAMO HUAIQUIN | O29: NICOLAS IGNACIO | P29: 18801412 | Q29: 7 | R29: ADMINISTRATIVO | S29: TRESOL
N30: CARCAMO OYARZUN | O30: NICOLAS | P30: 9929269 | Q30: 5 | R30: GERENTE GENERAL | S30: TRESOL | T30: KV BG 16
N31: CARDENAS ARTEAGA | O31: EGON JUAN | P31: 13404337 | Q31: 7 | R31: CONDUCTOR | S31: TRESOL
N32: CARDENAS ARTEAGA | O32: HECTOR ELIECER | P32: 12340833 | Q32: 0 | R32: OPERARIO | S32: TRESOL
N33: CARDENAS ROSAS | O33: ARMIN ANDESON | P33: 19269719 | Q33: 0 | R33: OPERARIO | S33: TRESOL
N34: CARRASCO VERGARA | O34: CARLOS ANYELO | P34: 15263602 | Q34: 4 | R34: OPERARIO | S34: TRESOL
N35: CARRASCO VERGARA | O35: CRISTIAN ISAIAS | P35: 13159173 | Q35: K | R35: CONDUCTOR | S35: TRESOL
N36: CARVAJAL SOTO | O36: FERNANDO MARCELO | P36: 20625206 | Q36: 5 | R36: OPERARIO DE SEGREGACIÓN | S36: TRESOL
N37: CASTRO APABLAZA | O37: JAIME PATRICIO | P37: 9871599 | Q37: 1 | R37: JEFE TALLER | S37: TRESOL
N38: CASTRO ROJAS | O38: ENRIQUE HERNAN | P38: 12215854 | Q38: 3 | R38: CONDUCTOR | S38: TRESOL
N39: CEA OYARZO | O39: OSCAR DANIEL | P39: 18287788 | Q39: 3 | R39: MECANICO | S39: TRESOL | T39: JZ WH 82
N40: COBOS RAMIREZ | O40: YSLANDIN DANNEL | P40: 26572030 | Q40: 7 | R40: OPERARIO | S40: ERSAN
N41: CONTRERAS MILLACHEO | O41: EDUARDO IGNACIO | P41: 18735696 | Q41: 2 | R41: CHOFER | S41: ERSAN | T41: KW HB 79
N42: CORONADO BARRIA | O42: HERNAN | P42: 10264143 | Q42: 4 | R42: JEFE DE FLOTA | S42: TRESOL | T42: JX YX 14
N43: CORONADO CARRASCO | O43: YONATAN ESTEBAN | P43: 17964277 | Q43: 8 | R43: OPERARIO | S43: TRESOL
...

Sheet 11
B2: ='10'!B2:M2+1 -> 45668
B4: REGISTRO DE INGRESO Y SALIDA DE TRABAJADORES Y PERSONAS EXTERNAS
B6: HORARIOS | T6: PATENTE
B7: ING. | C7: SAL. | D7: ING. | E7: SAL. | F7: ING. | G7: SAL. | H7: ING. | I7: SAL. | J7: ING. | K7: SAL. | L7: ING. | M7: SAL. | N7: APELLIDO | O7: NOMBRE | P7: RUT | Q7: DV | R7: CARGO | S7: EMPRESA | T7: Particular | U7: EMPRESA | V7: OBSERVACION
N8: AGÜERO | O8: MARTA | P8: 7009791 | Q8: 5 | R8: JUNIOR ASESOR | S8: PRIVADA | T8: HJ CP 67
N9: AGUILA SANCHEZ | O9: JUAN LUIS | P9: 13739164 | Q9: 3 | R9: CONTROL DE LOGISTICA | S9: TRESOL
N10: AGUILAR HERNANDEZ | O10: FRANCISCO | P10: 15734629 | Q10: 6 | R10: ASISTENTE RRHH | S10: TRESOL | T10: CH VD 16
N11: ALCAINO CARDENAS | O11: CLAUDIO ALEJANDRO | P11: 15847284 | Q11: 8 | R11: ASISTENTE DE LOGISTICA | S11: TRESOL
N12: ALMONACID SOTO | O12: JORGE PATRICIO | P12: 15285593 | Q12: 1 | R12: SOLDADOR | S12: TRESOL | T12: KMR714
N13: ALVARADO ALVARADO | O13: BERNARDO MARCELO | P13: 10106820 | Q13: K | R13: CHOFER | S13: ARIDOS | T13: HD FZ 51
N14: ALVARADO MELLA | O14: LUIS ADOLFO | P14: 20900423 | Q14: 2 | R14: AYUDANTE MECANICO | S14: TRESOL
N15: ALVARADO TORRES | O15: JORGE ANDRÉS | P15: 10772508 | Q15: 3 | R15: ENCARGADO DE ADQUISICIONES | S15: TRESOL
N16: AMPUERO MUÑOZ | O16: RAMON | P16: 13967856 | Q16: 7 | R16: GERENTE COMERCIAL-OPERACIONES | S16: TRESOL | T16: KB GD 89
N17: ANTIÑANCO PACHECO | O17: DANIEL FERNANDO | P17: 15301665 | Q17: 8 | R17: CONDUCTOR | S17: TRESOL
N18: ANTRIS ULLOA | O18: JOSE BENEDICTO | P18: 12714471 | Q18: 0 | R18: SOLDADOR | S18: TRESOL | T18: JJ FX 79
N19: ASENCIO CÁRCAMO | O19: CLAUDIA BELÉN | P19: 19367869 | Q19: 6 | R19: ASISTENTE CONTABLE DE FINANZAS | S19: TRESOL | T19: SR YP 72
N20: AVILA CHACON | O20: JULIO ANDRES | P20: 10587634 | Q20: 3 | R20: OPERADOR MAQUINA | S20: ARIDOS | T20: HS GB 34
N21: BARRIA | O21: PEDRO | P21: 20293903 | Q21: 1 | R21: OPERARIO CONDUCTOR | S21: TRESOL
N22: BARRIENTOS TORRES | O22: KENIA ALEJANDRA | P22: 17889059 | Q22: K | R22: ENCARGADA DE CASINO | S22: TRESOL
N23: BOHLE RODRIGUEZ | O23: BARBARA ALEJANDRA | P23: 18802330 | Q23: 4 | R23: ADMINISTRATIVO | S23: ERSAN
N24: BORDEN MUÑOZ | O24: JORGE AMERICO | P24: 13659758 | Q24: 2 | R24: CONDUCTOR | S24: TRESOL
N25: BUSTAMANTE VILLARROEL | O25: JORGE EDUARDO | P25: 9539333 | Q25: 0 | R25: AYUDANTE MECANICO | S25: TRESOL
N26: CÁCERES AROCA | O26: ROCÍO PAULINA | P26: 20773510 | Q26: 8 | R26: ASISTENTE DE LOGISTICA | S26: TRESOL | T26: CW XR 34
N27: CARCAMO CAUCAU | O27: ROBERTO CARLOS | P27: 13407096 | Q27: K | R27: CONDUCTOR | S27: TRESOL
N28: CARCAMO HUAIQUIN | O28: JAVIERA FRANCISCA | P28: 19962921 | Q28: 2 | R28: ADMINISTRATIVO | S28: TRESOL | T28: SL XY 20
N29: CARCAMO HUAIQUIN | O29: NICOLAS IGNACIO | P29: 18801412 | Q29: 7 | R29: ADMINISTRATIVO | S29: TRESOL
N30: CARCAMO OYARZUN | O30: NICOLAS | P30: 9929269 | Q30: 5 | R30: GERENTE GENERAL | S30: TRESOL | T30: KV BG 16
N31: CARDENAS ARTEAGA | O31: EGON JUAN | P31: 13404337 | Q31: 7 | R31: CONDUCTOR | S31: TRESOL
N32: CARDENAS ARTEAGA | O32: HECTOR ELIECER | P32: 12340833 | Q32: 0 | R32: OPERARIO | S32: TRESOL
N33: CARDENAS ROSAS | O33: ARMIN ANDESON | P33: 19269719 | Q33: 0 | R33: OPERARIO | S33: TRESOL
N34: CARRASCO VERGARA | O34: CARLOS ANYELO | P34: 15263602 | Q34: 4 | R34: OPERARIO | S34: TRESOL
N35: CARRASCO VERGARA | O35: CRISTIAN ISAIAS | P35: 13159173 | Q35: K | R35: CONDUCTOR | S35: TRESOL
N36: CARVAJAL SOTO | O36: FERNANDO MARCELO | P36: 20625206 | Q36: 5 | R36: OPERARIO DE SEGREGACIÓN | S36: TRESOL
N37: CASTRO APABLAZA | O37: JAIME PATRICIO | P37: 9871599 | Q37: 1 | R37: JEFE TALLER | S37: TRESOL
N38: CASTRO ROJAS | O38: ENRIQUE HERNAN | P38: 12215854 | Q38: 3 | R38: CONDUCTOR | S38: TRESOL
N39: CEA OYARZO | O39: OSCAR DANIEL | P39: 18287788 | Q39: 3 | R39: MECANICO | S39: TRESOL | T39: JZ WH 82
N40: COBOS RAMIREZ | O40: YSLANDIN DANNEL | P40: 26572030 | Q40: 7 | R40: OPERARIO | S40: ERSAN
N41: CONTRERAS MILLACHEO | O41: EDUARDO IGNACIO | P41: 18735696 | Q41: 2 | R41: CHOFER | S41: ERSAN | T41: KW HB 79
N42: CORONADO BARRIA | O42: HERNAN | P42: 10264143 | Q42: 4 | R42: JEFE DE FLOTA | S42: TRESOL | T42: JX YX 14
N43: CORONADO CARRASCO | O43: YONATAN ESTEBAN | P43: 17964277 | Q43: 8 | R43: OPERARIO | S43: TRESOL
...

Sheet 12
B2: ='11'!B2:M2+1 -> 45669
B4: REGISTRO DE INGRESO Y SALIDA DE TRABAJADORES Y PERSONAS EXTERNAS
B6: HORARIOS | T6: PATENTE
B7: ING. | C7: SAL. | D7: ING. | E7: SAL. | F7: ING. | G7: SAL. | H7: ING. | I7: SAL. | J7: ING. | K7: SAL. | L7: ING. | M7: SAL. | N7: APELLIDO | O7: NOMBRE | P7: RUT | Q7: DV | R7: CARGO | S7: EMPRESA | T7: Particular | U7: EMPRESA | V7: OBSERVACION
N8: AGÜERO | O8: MARTA | P8: 7009791 | Q8: 5 | R8: JUNIOR ASESOR | S8: PRIVADA | T8: HJ CP 67
N9: AGUILA SANCHEZ | O9: JUAN LUIS | P9: 13739164 | Q9: 3 | R9: CONTROL DE LOGISTICA | S9: TRESOL
N10: AGUILAR HERNANDEZ | O10: FRANCISCO | P10: 15734629 | Q10: 6 | R10: ASISTENTE RRHH | S10: TRESOL | T10: CH VD 16
N11: ALCAINO CARDENAS | O11: CLAUDIO ALEJANDRO | P11: 15847284 | Q11: 8 | R11: ASISTENTE DE LOGISTICA | S11: TRESOL
N12: ALMONACID SOTO | O12: JORGE PATRICIO | P12: 15285593 | Q12: 1 | R12: SOLDADOR | S12: TRESOL | T12: KMR714
N13: ALVARADO ALVARADO | O13: BERNARDO MARCELO | P13: 10106820 | Q13: K | R13: CHOFER | S13: ARIDOS | T13: HD FZ 51
N14: ALVARADO MELLA | O14: LUIS ADOLFO | P14: 20900423 | Q14: 2 | R14: AYUDANTE MECANICO | S14: TRESOL
N15: ALVARADO TORRES | O15: JORGE ANDRÉS | P15: 10772508 | Q15: 3 | R15: ENCARGADO DE ADQUISICIONES | S15: TRESOL
N16: AMPUERO MUÑOZ | O16: RAMON | P16: 13967856 | Q16: 7 | R16: GERENTE COMERCIAL-OPERACIONES | S16: TRESOL | T16: KB GD 89
N17: ANTIÑANCO PACHECO | O17: DANIEL FERNANDO | P17: 15301665 | Q17: 8 | R17: CONDUCTOR | S17: TRESOL
N18: ANTRIS ULLOA | O18: JOSE BENEDICTO | P18: 12714471 | Q18: 0 | R18: SOLDADOR | S18: TRESOL | T18: JJ FX 79
N19: ASENCIO CÁRCAMO | O19: CLAUDIA BELÉN | P19: 19367869 | Q19: 6 | R19: ASISTENTE CONTABLE DE FINANZAS | S19: TRESOL | T19: SR YP 72
N20: AVILA CHACON | O20: JULIO ANDRES | P20: 10587634 | Q20: 3 | R20: OPERADOR MAQUINA | S20: ARIDOS | T20: HS GB 34
N21: BARRIA | O21: PEDRO | P21: 20293903 | Q21: 1 | R21: OPERARIO CONDUCTOR | S21: TRESOL
N22: BARRIENTOS TORRES | O22: KENIA ALEJANDRA | P22: 17889059 | Q22: K | R22: ENCARGADA DE CASINO | S22: TRESOL
N23: BOHLE RODRIGUEZ | O23: BARBARA ALEJANDRA | P23: 18802330 | Q23: 4 | R23: ADMINISTRATIVO | S23: ERSAN
N24: BORDEN MUÑOZ | O24: JORGE AMERICO | P24: 13659758 | Q24: 2 | R24: CONDUCTOR | S24: TRESOL
N25: BUSTAMANTE VILLARROEL | O25: JORGE EDUARDO | P25: 9539333 | Q25: 0 | R25: AYUDANTE MECANICO | S25: TRESOL
N26: CÁCERES AROCA | O26: ROCÍO PAULINA | P26: 20773510 | Q26: 8 | R26: ASISTENTE DE LOGISTICA | S26: TRESOL | T26: CW XR 34
N27: CARCAMO CAUCAU | O27: ROBERTO CARLOS | P27: 13407096 | Q27: K | R27: CONDUCTOR | S27: TRESOL
N28: CARCAMO HUAIQUIN | O28: JAVIERA FRANCISCA | P28: 19962921 | Q28: 2 | R28: ADMINISTRATIVO | S28: TRESOL | T28: SL XY 20
N29: CARCAMO HUAIQUIN | O29: NICOLAS IGNACIO | P29: 18801412 | Q29: 7 | R29: ADMINISTRATIVO | S29: TRESOL
N30: CARCAMO OYARZUN | O30: NICOLAS | P30: 9929269 | Q30: 5 | R30: GERENTE GENERAL | S30: TRESOL | T30: KV BG 16
N31: CARDENAS ARTEAGA | O31: EGON JUAN | P31: 13404337 | Q31: 7 | R31: CONDUCTOR | S31: TRESOL
N32: CARDENAS ARTEAGA | O32: HECTOR ELIECER | P32: 12340833 | Q32: 0 | R32: OPERARIO | S32: TRESOL
N33: CARDENAS ROSAS | O33: ARMIN ANDESON | P33: 19269719 | Q33: 0 | R33: OPERARIO | S33: TRESOL
N34: CARRASCO VERGARA | O34: CARLOS ANYELO | P34: 15263602 | Q34: 4 | R34: OPERARIO | S34: TRESOL
N35: CARRASCO VERGARA | O35: CRISTIAN ISAIAS | P35: 13159173 | Q35: K | R35: CONDUCTOR | S35: TRESOL
N36: CARVAJAL SOTO | O36: FERNANDO MARCELO | P36: 20625206 | Q36: 5 | R36: OPERARIO DE SEGREGACIÓN | S36: TRESOL
N37: CASTRO APABLAZA | O37: JAIME PATRICIO | P37: 9871599 | Q37: 1 | R37: JEFE TALLER | S37: TRESOL
N38: CASTRO ROJAS | O38: ENRIQUE HERNAN | P38: 12215854 | Q38: 3 | R38: CONDUCTOR | S38: TRESOL
N39: CEA OYARZO | O39: OSCAR DANIEL | P39: 18287788 | Q39: 3 | R39: MECANICO | S39: TRESOL | T39: JZ WH 82
N40: COBOS RAMIREZ | O40: YSLANDIN DANNEL | P40: 26572030 | Q40: 7 | R40: OPERARIO | S40: ERSAN
N41: CONTRERAS MILLACHEO | O41: EDUARDO IGNACIO | P41: 18735696 | Q41: 2 | R41: CHOFER | S41: ERSAN | T41: KW HB 79
N42: CORONADO BARRIA | O42: HERNAN | P42: 10264143 | Q42: 4 | R42: JEFE DE FLOTA | S42: TRESOL | T42: JX YX 14
N43: CORONADO CARRASCO | O43: YONATAN ESTEBAN | P43: 17964277 | Q43: 8 | R43: OPERARIO | S43: TRESOL
...

Sheet 13
B2: ='12'!B2:M2+1 -> 45670
B4: REGISTRO DE INGRESO Y SALIDA DE TRABAJADORES Y PERSONAS EXTERNAS
B6: HORARIOS | T6: PATENTE
B7: ING. | C7: SAL. | D7: ING. | E7: SAL. | F7: ING. | G7: SAL. | H7: ING. | I7: SAL. | J7: ING. | K7: SAL. | L7: ING. | M7: SAL. | N7: APELLIDO | O7: NOMBRE | P7: RUT | Q7: DV | R7: CARGO | S7: EMPRESA | T7: Particular | U7: EMPRESA | V7: OBSERVACION
N8: AGÜERO | O8: MARTA | P8: 7009791 | Q8: 5 | R8: JUNIOR ASESOR | S8: PRIVADA | T8: HJ CP 67
N9: AGUILA SANCHEZ | O9: JUAN LUIS | P9: 13739164 | Q9: 3 | R9: CONTROL DE LOGISTICA | S9: TRESOL
N10: AGUILAR HERNANDEZ | O10: FRANCISCO | P10: 15734629 | Q10: 6 | R10: ASISTENTE RRHH | S10: TRESOL | T10: CH VD 16
N11: ALCAINO CARDENAS | O11: CLAUDIO ALEJANDRO | P11: 15847284 | Q11: 8 | R11: ASISTENTE DE LOGISTICA | S11: TRESOL
N12: ALMONACID SOTO | O12: JORGE PATRICIO | P12: 15285593 | Q12: 1 | R12: SOLDADOR | S12: TRESOL | T12: KMR714
N13: ALVARADO ALVARADO | O13: BERNARDO MARCELO | P13: 10106820 | Q13: K | R13: CHOFER | S13: ARIDOS | T13: HD FZ 51
N14: ALVARADO MELLA | O14: LUIS ADOLFO | P14: 20900423 | Q14: 2 | R14: AYUDANTE MECANICO | S14: TRESOL
N15: ALVARADO TORRES | O15: JORGE ANDRÉS | P15: 10772508 | Q15: 3 | R15: ENCARGADO DE ADQUISICIONES | S15: TRESOL
N16: AMPUERO MUÑOZ | O16: RAMON | P16: 13967856 | Q16: 7 | R16: GERENTE COMERCIAL-OPERACIONES | S16: TRESOL | T16: KB GD 89
N17: ANTIÑANCO PACHECO | O17: DANIEL FERNANDO | P17: 15301665 | Q17: 8 | R17: CONDUCTOR | S17: TRESOL
N18: ANTRIS ULLOA | O18: JOSE BENEDICTO | P18: 12714471 | Q18: 0 | R18: SOLDADOR | S18: TRESOL | T18: JJ FX 79
N19: ASENCIO CÁRCAMO | O19: CLAUDIA BELÉN | P19: 19367869 | Q19: 6 | R19: ASISTENTE CONTABLE DE FINANZAS | S19: TRESOL | T19: SR YP 72
N20: AVILA CHACON | O20: JULIO ANDRES | P20: 10587634 | Q20: 3 | R20: OPERADOR MAQUINA | S20: ARIDOS | T20: HS GB 34
N21: BARRIA | O21: PEDRO | P21: 20293903 | Q21: 1 | R21: OPERARIO CONDUCTOR | S21: TRESOL
N22: BARRIENTOS TORRES | O22: KENIA ALEJANDRA | P22: 17889059 | Q22: K | R22: ENCARGADA DE CASINO | S22: TRESOL
N23: BOHLE RODRIGUEZ | O23: BARBARA ALEJANDRA | P23: 18802330 | Q23: 4 | R23: ADMINISTRATIVO | S23: ERSAN
N24: BORDEN MUÑOZ | O24: JORGE AMERICO | P24: 13659758 | Q24: 2 | R24: CONDUCTOR | S24: TRESOL
N25: BUSTAMANTE VILLARROEL | O25: JORGE EDUARDO | P25: 9539333 | Q25: 0 | R25: AYUDANTE MECANICO | S25: TRESOL
N26: CÁCERES AROCA | O26: ROCÍO PAULINA | P26: 20773510 | Q26: 8 | R26: ASISTENTE DE LOGISTICA | S26: TRESOL | T26: CW XR 34
N27: CARCAMO CAUCAU | O27: ROBERTO CARLOS | P27: 13407096 | Q27: K | R27: CONDUCTOR | S27: TRESOL
N28: CARCAMO HUAIQUIN | O28: JAVIERA FRANCISCA | P28: 19962921 | Q28: 2 | R28: ADMINISTRATIVO | S28: TRESOL | T28: SL XY 20
N29: CARCAMO HUAIQUIN | O29: NICOLAS IGNACIO | P29: 18801412 | Q29: 7 | R29: ADMINISTRATIVO | S29: TRESOL
N30: CARCAMO OYARZUN | O30: NICOLAS | P30: 9929269 | Q30: 5 | R30: GERENTE GENERAL | S30: TRESOL | T30: KV BG 16
N31: CARDENAS ARTEAGA | O31: EGON JUAN | P31: 13404337 | Q31: 7 | R31: CONDUCTOR | S31: TRESOL
N32: CARDENAS ARTEAGA | O32: HECTOR ELIECER | P32: 12340833 | Q32: 0 | R32: OPERARIO | S32: TRESOL
N33: CARDENAS ROSAS | O33: ARMIN ANDESON | P33: 19269719 | Q33: 0 | R33: OPERARIO | S33: TRESOL
N34: CARRASCO VERGARA | O34: CARLOS ANYELO | P34: 15263602 | Q34: 4 | R34: OPERARIO | S34: TRESOL
N35: CARRASCO VERGARA | O35: CRISTIAN ISAIAS | P35: 13159173 | Q35: K | R35: CONDUCTOR | S35: TRESOL
N36: CARVAJAL SOTO | O36: FERNANDO MARCELO | P36: 20625206 | Q36: 5 | R36: OPERARIO DE SEGREGACIÓN | S36: TRESOL
N37: CASTRO APABLAZA | O37: JAIME PATRICIO | P37: 9871599 | Q37: 1 | R37: JEFE TALLER | S37: TRESOL
N38: CASTRO ROJAS | O38: ENRIQUE HERNAN | P38: 12215854 | Q38: 3 | R38: CONDUCTOR | S38: TRESOL
N39: CEA OYARZO | O39: OSCAR DANIEL | P39: 18287788 | Q39: 3 | R39: MECANICO | S39: TRESOL | T39: JZ WH 82
N40: COBOS RAMIREZ | O40: YSLANDIN DANNEL | P40: 26572030 | Q40: 7 | R40: OPERARIO | S40: ERSAN
N41: CONTRERAS MILLACHEO | O41: EDUARDO IGNACIO | P41: 18735696 | Q41: 2 | R41: CHOFER | S41: ERSAN | T41: KW HB 79
N42: CORONADO BARRIA | O42: HERNAN | P42: 10264143 | Q42: 4 | R42: JEFE DE FLOTA | S42: TRESOL | T42: JX YX 14
N43: CORONADO CARRASCO | O43: YONATAN ESTEBAN | P43: 17964277 | Q43: 8 | R43: OPERARIO | S43: TRESOL
...

Sheet 14
B2: ='13'!B2:M2+1 -> 45671
B4: REGISTRO DE INGRESO Y SALIDA DE TRABAJADORES Y PERSONAS EXTERNAS
B6: HORARIOS | T6: PATENTE
B7: ING. | C7: SAL. | D7: ING. | E7: SAL. | F7: ING. | G7: SAL. | H7: ING. | I7: SAL. | J7: ING. | K7: SAL. | L7: ING. | M7: SAL. | N7: APELLIDO | O7: NOMBRE | P7: RUT | Q7: DV | R7: CARGO | S7: EMPRESA | T7: Particular | U7: EMPRESA | V7: OBSERVACION
N8: AGÜERO | O8: MARTA | P8: 7009791 | Q8: 5 | R8: JUNIOR ASESOR | S8: PRIVADA | T8: HJ CP 67
N9: AGUILA SANCHEZ | O9: JUAN LUIS | P9: 13739164 | Q9: 3 | R9: CONTROL DE LOGISTICA | S9: TRESOL
N10: AGUILAR HERNANDEZ | O10: FRANCISCO | P10: 15734629 | Q10: 6 | R10: ASISTENTE RRHH | S10: TRESOL | T10: CH VD 16
N11: ALCAINO CARDENAS | O11: CLAUDIO ALEJANDRO | P11: 15847284 | Q11: 8 | R11: ASISTENTE DE LOGISTICA | S11: TRESOL
N12: ALMONACID SOTO | O12: JORGE PATRICIO | P12: 15285593 | Q12: 1 | R12: SOLDADOR | S12: TRESOL | T12: KMR714
N13: ALVARADO ALVARADO | O13: BERNARDO MARCELO | P13: 10106820 | Q13: K | R13: CHOFER | S13: ARIDOS | T13: HD FZ 51
N14: ALVARADO MELLA | O14: LUIS ADOLFO | P14: 20900423 | Q14: 2 | R14: AYUDANTE MECANICO | S14: TRESOL
N15: ALVARADO TORRES | O15: JORGE ANDRÉS | P15: 10772508 | Q15: 3 | R15: ENCARGADO DE ADQUISICIONES | S15: TRESOL
N16: AMPUERO MUÑOZ | O16: RAMON | P16: 13967856 | Q16: 7 | R16: GERENTE COMERCIAL-OPERACIONES | S16: TRESOL | T16: KB GD 89
N17: ANTIÑANCO PACHECO | O17: DANIEL FERNANDO | P17: 15301665 | Q17: 8 | R17: CONDUCTOR | S17: TRESOL
N18: ANTRIS ULLOA | O18: JOSE BENEDICTO | P18: 12714471 | Q18: 0 | R18: SOLDADOR | S18: TRESOL | T18: JJ FX 79
N19: ASENCIO CÁRCAMO | O19: CLAUDIA BELÉN | P19: 19367869 | Q19: 6 | R19: ASISTENTE CONTABLE DE FINANZAS | S19: TRESOL | T19: SR YP 72
N20: AVILA CHACON | O20: JULIO ANDRES | P20: 10587634 | Q20: 3 | R20: OPERADOR MAQUINA | S20: ARIDOS | T20: HS GB 34
N21: BARRIA | O21: PEDRO | P21: 20293903 | Q21: 1 | R21: OPERARIO CONDUCTOR | S21: TRESOL
N22: BARRIENTOS TORRES | O22: KENIA ALEJANDRA | P22: 17889059 | Q22: K | R22: ENCARGADA DE CASINO | S22: TRESOL
N23: BOHLE RODRIGUEZ | O23: BARBARA ALEJANDRA | P23: 18802330 | Q23: 4 | R23: ADMINISTRATIVO | S23: ERSAN
N24: BORDEN MUÑOZ | O24: JORGE AMERICO | P24: 13659758 | Q24: 2 | R24: CONDUCTOR | S24: TRESOL
N25: BUSTAMANTE VILLARROEL | O25: JORGE EDUARDO | P25: 9539333 | Q25: 0 | R25: AYUDANTE MECANICO | S25: TRESOL
N26: CÁCERES AROCA | O26: ROCÍO PAULINA | P26: 20773510 | Q26: 8 | R26: ASISTENTE DE LOGISTICA | S26: TRESOL | T26: CW XR 34
N27: CARCAMO CAUCAU | O27: ROBERTO CARLOS | P27: 13407096 | Q27: K | R27: CONDUCTOR | S27: TRESOL
N28: CARCAMO HUAIQUIN | O28: JAVIERA FRANCISCA | P28: 19962921 | Q28: 2 | R28: ADMINISTRATIVO | S28: TRESOL | T28: SL XY 20
N29: CARCAMO HUAIQUIN | O29: NICOLAS IGNACIO | P29: 18801412 | Q29: 7 | R29: ADMINISTRATIVO | S29: TRESOL
N30: CARCAMO OYARZUN | O30: NICOLAS | P30: 9929269 | Q30: 5 | R30: GERENTE GENERAL | S30: TRESOL | T30: KV BG 16
N31: CARDENAS ARTEAGA | O31: EGON JUAN | P31: 13404337 | Q31: 7 | R31: CONDUCTOR | S31: TRESOL
N32: CARDENAS ARTEAGA | O32: HECTOR ELIECER | P32: 12340833 | Q32: 0 | R32: OPERARIO | S32: TRESOL
N33: CARDENAS ROSAS | O33: ARMIN ANDESON | P33: 19269719 | Q33: 0 | R33: OPERARIO | S33: TRESOL
N34: CARRASCO VERGARA | O34: CARLOS ANYELO | P34: 15263602 | Q34: 4 | R34: OPERARIO | S34: TRESOL
N35: CARRASCO VERGARA | O35: CRISTIAN ISAIAS | P35: 13159173 | Q35: K | R35: CONDUCTOR | S35: TRESOL
N36: CARVAJAL SOTO | O36: FERNANDO MARCELO | P36: 20625206 | Q36: 5 | R36: OPERARIO DE SEGREGACIÓN | S36: TRESOL
N37: CASTRO APABLAZA | O37: JAIME PATRICIO | P37: 9871599 | Q37: 1 | R37: JEFE TALLER | S37: TRESOL
N38: CASTRO ROJAS | O38: ENRIQUE HERNAN | P38: 12215854 | Q38: 3 | R38: CONDUCTOR | S38: TRESOL
N39: CEA OYARZO | O39: OSCAR DANIEL | P39: 18287788 | Q39: 3 | R39: MECANICO | S39: TRESOL | T39: JZ WH 82
N40: COBOS RAMIREZ | O40: YSLANDIN DANNEL | P40: 26572030 | Q40: 7 | R40: OPERARIO | S40: ERSAN
N41: CONTRERAS MILLACHEO | O41: EDUARDO IGNACIO | P41: 18735696 | Q41: 2 | R41: CHOFER | S41: ERSAN | T41: KW HB 79
N42: CORONADO BARRIA | O42: HERNAN | P42: 10264143 | Q42: 4 | R42: JEFE DE FLOTA | S42: TRESOL | T42: JX YX 14
N43: CORONADO CARRASCO | O43: YONATAN ESTEBAN | P43: 17964277 | Q43: 8 | R43: OPERARIO | S43: TRESOL
...

Sheet 15
B2: ='14'!B2:M2+1 -> 45672
B4: REGISTRO DE INGRESO Y SALIDA DE TRABAJADORES Y PERSONAS EXTERNAS
B6: HORARIOS | T6: PATENTE
B7: ING. | C7: SAL. | D7: ING. | E7: SAL. | F7: ING. | G7: SAL. | H7: ING. | I7: SAL. | J7: ING. | K7: SAL. | L7: ING. | M7: SAL. | N7: APELLIDO | O7: NOMBRE | P7: RUT | Q7: DV | R7: CARGO | S7: EMPRESA | T7: Particular | U7: EMPRESA | V7: OBSERVACION
N8: AGÜERO | O8: MARTA | P8: 7009791 | Q8: 5 | R8: JUNIOR ASESOR | S8: PRIVADA | T8: HJ CP 67
N9: AGUILA SANCHEZ | O9: JUAN LUIS | P9: 13739164 | Q9: 3 | R9: CONTROL DE LOGISTICA | S9: TRESOL
